Workbook

Sheet Student Choices
A1: Timestamp | B1: Email Address | C1: PID | D1: Full Name | E1: Resume | F1: Credits completed as of Spring 2026. Only include courses where you have a passing grade or higher. If you are a transfer student include in this number any transferred credits. | G1: GPA | H1: Pre-requisites for DSC 180A - Please check these carefully before you certify. It is entirely your responsibility to ensure eligibility. | I1: First Preference | J1: Second Preference | K1: Third Preference | L1: Fourth Preference | M1: Fifth Preference | N1: Sixth Preference | O1: Seventh Preference | P1: Eighth Preference | Q1: Ninth Preference | R1: Tenth Preference
A2: 46195.966 | B2: rgautama@ucsd.edu | C2: A18546099 | D2: Rezon Gautama | E2: https://drive.google.com/file/d/1twfNFXw5etJwb4VSLD3lrfpHA1-lon9T/view?usp=sharing | F2: 247 | G2: 3.67 | H2: I certify that I have completed the pre-requisites listed at https://datascience.ucsd.edu/current-students/course-descriptions-and-prerequisites/#dsc-180a-data-science-project-1 and I am eligible to enroll in DSC 180A. | I2: D01 | J2: D36 | K2: D37 | L2: D23 | M2: D28 | N2: D05 | O2: D08 | P2: D10 | Q2: D12 | R2: D42
A3: 46195.995 | B3: abalasai@ucsd.edu | C3: A19290181 | D3: Akshitaa Balasai | E3: https://drive.google.com/file/d/10O0wApXn_zQWFXEhmn8QHxOPJNKswQns/view?usp=sharing | F3: 228 | G3: 3.64 | H3: I certify that I have completed the pre-requisites listed at https://datascience.ucsd.edu/current-students/course-descriptions-and-prerequisites/#dsc-180a-data-science-project-1 and I am eligible to enroll in DSC 180A. | I3: D01 | J3: D25 | K3: D21 | L3: D02 | M3: D31
A4: 46195.263 | B4: hez018@ucsd.edu | C4: A17872179 | D4: Bobby Zhou | E4: https://drive.google.com/file/d/1OdPD6UYzLG_Y4mVp0174_uVN121_jBqG/view?usp=sharing | F4: 226.5 | G4: 3.86 | H4: I certify that I have completed the pre-requisites listed at https://datascience.ucsd.edu/current-students/course-descriptions-and-prerequisites/#dsc-180a-data-science-project-1 and I am eligible to enroll in DSC 180A. | I4: D01 | J4: D21 | K4: D28 | L4: D23 | M4: D30
A5: 46195.94 | B5: gtrainor@ucsd.edu | C5: A17770083 | D5: Grace Trainor | E5: https://www.overleaf.com/read/yqfxvtzpvnjy#6cd4a7 | F5: 226 | G5: 3.773 | H5: I certify that I have completed the pre-requisites listed at https://datascience.ucsd.edu/current-students/course-descriptions-and-prerequisites/#dsc-180a-data-science-project-1 and I am eligible to enroll in DSC 180A. | I5: D01 | J5: D23 | K5: D12 | L5: D11 | M5: D37 | N5: D14 | O5: D16 | P5: D43 | Q5: D36 | R5: D06
A6: 46195.807 | B6: kyflores@ucsd.edu | C6: A17849396 | D6: Kyle Flores | E6: https://drive.google.com/file/d/1zwS5u-TJN50QF47woEu45rtxNHNUDwET/view?usp=drivesdk | F6: 221.5 | G6: 3.805 | H6: I certify that I have completed the pre-requisites listed at https://datascience.ucsd.edu/current-students/course-descriptions-and-prerequisites/#dsc-180a-data-science-project-1 and I am eligible to enroll in DSC 180A. | I6: D01 | J6: D42 | K6: D12 | L6: D05 | M6: D23 | N6: D08 | O6: D04 | P6: D15 | Q6: D02 | R6: D14
A7: 46195.962 | B7: valau@ucsd.edu | C7: A17827322 | D7: Vanessa Lau | E7: https://drive.google.com/file/d/1lq3IDAg13eknDvP9t9asJQljJQw-3j-w/view?usp=sharing | F7: 218.5 | G7: 3.934 | H7: I certify that I have completed the pre-requisites listed at https://datascience.ucsd.edu/current-students/course-descriptions-and-prerequisites/#dsc-180a-data-science-project-1 and I am eligible to enroll in DSC 180A. | I7: D01 | J7: D20 | K7: D21 | L7: D26 | M7: D43 | N7: D18 | O7: D23 | P7: D16 | Q7: D24 | R7: D12
A8: 46194.724 | B8: sirao@ucsd.edu | C8: A17829997 | D8: Simone Rao | E8: https://drive.google.com/file/d/1RQoLoxeF9bAs5oAVPDSqpd4OrQ8mtB4G/view?usp=sharing | F8: 204 | G8: 3.651 | H8: I certify that I have completed the pre-requisites listed at https://datascience.ucsd.edu/current-students/course-descriptions-and-prerequisites/#dsc-180a-data-science-project-1 and I am eligible to enroll in DSC 180A. | I8: D01 | J8: D24 | K8: D07 | L8: D28 | M8: D26 | N8: D37 | O8: D30 | P8: D23 | Q8: D36 | R8: D08
A9: 46191.529 | B9: cll016@ucsd.edu | C9: A17815340 | D9: Claire Lee | E9: https://drive.google.com/file/d/15zSKD9c38UGueY1pKI00lD8uOl6nB5PR/view?usp=sharing | F9: 198.5 | G9: 3.69 | H9: I certify that I have completed the pre-requisites listed at https://datascience.ucsd.edu/current-students/course-descriptions-and-prerequisites/#dsc-180a-data-science-project-1 and I am eligible to enroll in DSC 180A. | I9: D01 | J9: D05 | K9: D08 | L9: D19 | M9: D15 | N9: D37 | O9: D14 | P9: D12 | Q9: D08 | R9: D21
A10: 46195.556 | B10: ala023@ucsd.edu | C10: A18523333 | D10: Ali Ahmed | E10: https://drive.google.com/file/d/1NiJ46msTHKec6EqQScYrWfu_-NPvo_mn/view?usp=sharing | F10: 194.5 | G10: 3.36 | H10: I certify that I have completed the pre-requisites listed at https://datascience.ucsd.edu/current-students/course-descriptions-and-prerequisites/#dsc-180a-data-science-project-1 and I am eligible to enroll in DSC 180A. | I10: D01 | J10: D12 | K10: D23 | L10: D28 | M10: D05 | N10: D11 | O10: D42 | P10: D44 | Q10: D21 | R10: D34
A11: 46191.439 | B11: jrinconrodriguez@ucsd.edu | C11: A18552804 | D11: Janice Rincon | E11: https://drive.google.com/drive/folders/1WU_mF82LYenfFu51R6pe_eTsrNI2Cxjq?usp=drive_link | F11: 194 | G11: 3.84 | H11: I certify that I have completed the pre-requisites listed at https://datascience.ucsd.edu/current-students/course-descriptions-and-prerequisites/#dsc-180a-data-science-project-1 and I am eligible to enroll in DSC 180A. | I11: D01 | J11: D23 | K11: D12 | L11: D33 | M11: D28 | N11: D11 | O11: D37 | P11: D06 | Q11: D14 | R11: D05
A12: 46190.877 | B12: sranadive@ucsd.edu | C12: A17860402 | D12: Saanvi Ranadive | E12: https://drive.google.com/file/d/1saTF-GzQ9Jcsilj_v_8SyLpTx3wsROMH/view?usp=sharing | F12: 193 | G12: 3.98 | H12: I certify that I have completed the pre-requisites listed at https://datascience.ucsd.edu/current-students/course-descriptions-and-prerequisites/#dsc-180a-data-science-project-1 and I am eligible to enroll in DSC 180A. | I12: D01 | J12: D20 | K12: D02 | L12: D06 | M12: D33 | N12: D22 | O12: D43 | P12: D12 | Q12: D39 | R12: D18
A13: 46193.769 | B13: wayang@ucsd.edu | C13: A18500359 | D13: Wanchen Yang | F13: 189 | G13: 3.104 | H13: I certify that I have completed the pre-requisites listed at https://datascience.ucsd.edu/current-students/course-descriptions-and-prerequisites/#dsc-180a-data-science-project-1 and I am eligible to enroll in DSC 180A. | I13: D01 | J13: D17 | K13: D21 | L13: D22 | M13: D38 | N13: D30 | O13: D24 | P13: D26 | Q13: D39 | R13: D32
A14: 46190.638 | B14: ertong@ucsd.edu | C14: A17769869 | D14: Erika Tong | E14: https://docs.google.com/document/d/1s0FTBgGXQn8bXy7MP_7EAsIdBC3yPBbFNKNfJhWd3Ng/edit?usp=sharing | F14: 184 | G14: 3.591 | H14: I certify that I have completed the pre-requisites listed at https://datascience.ucsd.edu/current-students/course-descriptions-and-prerequisites/#dsc-180a-data-science-project-1 and I am eligible to enroll in DSC 180A. | I14: D01 | J14: D12 | K14: D15 | L14: D11 | M14: D42 | N14: D08 | O14: D17
A15: 46193.828 | B15: edayran@ucsd.edu | C15: A17846462 | D15: Edison Ayran | E15: https://docs.google.com/document/d/1ShMuDMpQQQRo6ddQe3t_RIuy9CbUqH95jZtIH4M5yr0/edit?usp=drivesdk | F15: 178 | G15: 3.4 | H15: I certify that I have completed the pre-requisites listed at https://datascience.ucsd.edu/current-students/course-descriptions-and-prerequisites/#dsc-180a-data-science-project-1 and I am eligible to enroll in DSC 180A. | I15: D01 | J15: D23 | K15: D28 | L15: D38 | M15: D33 | N15: D15 | O15: D12 | P15: D21 | Q15: D25 | R15: D30
A16: 46193.01 | B16: dsehgal@ucsd.edu | C16: A17853941 | D16: Dhruv Sehgal | E16: https://www.overleaf.com/read/wkmsvmqtyszp#0baec9 | F16: 175 | G16: 3.87 | H16: I certify that I have completed the pre-requisites listed at https://datascience.ucsd.edu/current-students/course-descriptions-and-prerequisites/#dsc-180a-data-science-project-1 and I am eligible to enroll in DSC 180A. | I16: D01 | J16: D44 | K16: D11 | L16: D03 | M16: D10 | N16: D14 | O16: D08 | P16: D36 | Q16: D37 | R16: D06
A17: 46195.993 | B17: amuthu@ucsd.edu | C17: A17813042 | D17: Aathi Muthu | E17: https://drive.google.com/file/d/18ntvq1A4dvOryNTbQRZQPtIEO4S2BYR0/view?usp=sharing | F17: 170 | G17: 3.737 | H17: I certify that I have completed the pre-requisites listed at https://datascience.ucsd.edu/current-students/course-descriptions-and-prerequisites/#dsc-180a-data-science-project-1 and I am eligible to enroll in DSC 180A. | I17: D01 | J17: D34 | K17: D38 | L17: D28 | M17: D23
A18: 46195.637 | B18: surai@ucsd.edu | C18: A18605782 | D18: Sumedha Rai | E18: https://drive.google.com/file/d/1I8GESX7tQgVmJtVE0Un8d9FahcCbig-Z/view?usp=sharing | F18: 162 | G18: 3.72 | H18: I certify that I have completed the pre-requisites listed at https://datascience.ucsd.edu/current-students/course-descriptions-and-prerequisites/#dsc-180a-data-science-project-1 and I am eligible to enroll in DSC 180A. | I18: D01 | J18: D08 | K18: D23 | L18: D07 | M18: D24 | N18: D29 | O18: D03 | P18: D10 | Q18: D12 | R18: D20
A19: 46190.797 | B19: mndubisi@ucsd.edu | C19: A17852643 | D19: Munachimso Ndubisi | E19: https://drive.google.com/file/d/1ONbVQ9s53VMu6B9eQBBxmuHICo4jeklw/view?usp=sharing | F19: 148 | G19: 3.79 | H19: I certify that I have completed the pre-requisites listed at https://datascience.ucsd.edu/current-students/course-descriptions-and-prerequisites/#dsc-180a-data-science-project-1 and I am eligible to enroll in DSC 180A. | I19: D01 | J19: D12 | K19: D15 | L19: D19 | M19: D07 | N19: D03 | O19: D42 | P19: D17 | Q19: D43 | R19: D14
A20: 46192.535 | B20: vpaidi@ucsd.edu | C20: A17924639 | D20: Vishal Rana Paidi | E20: https://docs.google.com/document/d/1LlHZDTTSHoS6xql-Uml8OBqczZaCp0-MbVh6vm-9pFM/edit?usp=drivesdk | F20: 144 | G20: 3.415 | H20: I certify that I have completed the pre-requisites listed at https://datascience.ucsd.edu/current-students/course-descriptions-and-prerequisites/#dsc-180a-data-science-project-1 and I am eligible to enroll in DSC 180A. | I20: D01 | J20: D06 | K20: D10 | L20: D12 | M20: D35
A21: 46195.709 | B21: cclougherty@ucsd.edu | C21: A18282418 | D21: Coleman Clougherty | E21: https://drive.google.com/file/d/1L5D0Tq3aacpcCUKAEMTMwh8bzo7mAZbD/view?usp=sharing | F21: 126 | G21: 3.988 | H21: I certify that I have completed the pre-requisites listed at https://datascience.ucsd.edu/current-students/course-descriptions-and-prerequisites/#dsc-180a-data-science-project-1 and I am eligible to enroll in DSC 180A. | I21: D01 | J21: D06 | K21: D15 | L21: D31 | M21: D02 | N21: D42 | O21: D14 | P21: D11 | Q21: D41 | R21: D28
A22: 46193.596 | B22: imansfield@ucsd.edu | C22: A17715152 | D22: Lyn Mansfield | E22: https://docs.google.com/document/d/10tchVqFkX4eQRxi-f5HMsTNAq1v7GqZdooKZUaxkOXA/edit?usp=sharing | F22: 122 | G22: 3.84 | H22: I certify that I have completed the pre-requisites listed at https://datascience.ucsd.edu/current-students/course-descriptions-and-prerequisites/#dsc-180a-data-science-project-1 and I am eligible to enroll in DSC 180A. | I22: D01 | J22: D28 | K22: D36 | L22: D13 | M22: D30 | N22: D26
A23: 46195.117 | B23: ratienza@ucsd.edu | C23: A17902620 | D23: Ryan Conrad Atienza | E23: https://popokeyry.github.io/portfolio/resume/ | F23: 196 | G23: 3.66 | H23: I certify that I have completed the pre-requisites listed at https://datascience.ucsd.edu/current-students/course-descriptions-and-prerequisites/#dsc-180a-data-science-project-1 and I am eligible to enroll in DSC 180A. | I23: D02 | J23: D01 | K23: D06 | L23: D14 | M23: D08 | N23: D16 | O23: D28 | P23: D20 | Q23: D12 | R23: D29
A24: 46176.614 | B24: t2harmon@ucsd.edu | C24: A18251274 | D24: Timothy Harmon | E24: https://drive.google.com/file/d/1YcMh_eS0fUbQIJ0BMmR8NTgHYixYPJKa/view?usp=sharing | F24: 187 | G24: 3.91 | H24: I certify that I have completed the pre-requisites listed at https://datascience.ucsd.edu/current-students/course-descriptions-and-prerequisites/#dsc-180a-data-science-project-1 and I am eligible to enroll in DSC 180A. | I24: D02 | J24: D33 | K24: D28 | L24: D31 | M24: D39
A25: 46195.894 | B25: bscruz@ucsd.edu | C25: A18578660 | D25: Bryan Cruz | E25: https://docs.google.com/document/d/13X1KsziWs9D5AuZ48KEqMhYFV5JZ46bZ0-yydnjGSsQ/edit?usp=share_link | F25: 181 | G25: 3.442 | H25: I certify that I have completed the pre-requisites listed at https://datascience.ucsd.edu/current-students/course-descriptions-and-prerequisites/#dsc-180a-data-science-project-1 and I am eligible to enroll in DSC 180A. | I25: D02 | J25: D42 | K25: D03 | L25: D43 | M25: D01 | N25: D05 | O25: D06 | P25: D16 | Q25: D12 | R25: D22
A26: 46194.683 | B26: alw054@ucsd.edu | C26: A18592255 | D26: Alisha Wang | E26: https://drive.google.com/file/d/11b_Py6OiqQB0BJZGNwuBdN-2p-dqt5Kr/view?usp=sharing | F26: 276 | G26: 3.923 | H26: I certify that I have completed the pre-requisites listed at https://datascience.ucsd.edu/current-students/course-descriptions-and-prerequisites/#dsc-180a-data-science-project-1 and I am eligible to enroll in DSC 180A. | I26: D03 | J26: D12 | K26: D28 | L26: D08 | M26: D29 | N26: D42 | O26: D14 | P26: D05
A27: 46195.407 | B27: vil018@ucsd.edu | C27: A17719081 | D27: Vivian Lin | E27: https://drive.google.com/file/d/1dKw4rOmVGj4jXhbVgmpucRu3-EOf7mWy/view?usp=sharing | F27: 235 | G27: 3.86 | H27: I certify that I have completed the pre-requisites listed at https://datascience.ucsd.edu/current-students/course-descriptions-and-prerequisites/#dsc-180a-data-science-project-1 and I am eligible to enroll in DSC 180A. | I27: D03 | J27: D12 | K27: D08 | L27: D16 | M27: D43 | N27: D18
A28: 46191.587 | B28: amz004@ucsd.edu | C28: A18110768 | D28: Amy Zhao | F28: 220 | G28: 3.8 | H28: I certify that I have completed the pre-requisites listed at https://datascience.ucsd.edu/current-students/course-descriptions-and-prerequisites/#dsc-180a-data-science-project-1 and I am eligible to enroll in DSC 180A. | I28: D03 | J28: D15 | K28: D43 | L28: D19 | M28: D01 | N28: D22 | O28: D06 | P28: D11 | Q28: D14 | R28: D16
A29: 46194.591 | B29: mavaught@ucsd.edu | C29: A17887951 | D29: Matthew Vaught | E29: https://drive.google.com/file/d/1ut421xnPtIvwaeuleLnsGbUT-JWJllqU/view?usp=sharing | F29: 190 | G29: 3.84 | H29: I certify that I have completed the pre-requisites listed at https://datascience.ucsd.edu/current-students/course-descriptions-and-prerequisites/#dsc-180a-data-science-project-1 and I am eligible to enroll in DSC 180A. | I29: D03 | J29: D01 | K29: D28 | L29: D43 | M29: D02 | N29: D13 | O29: D23 | P29: D12 | Q29: D15
A30: 46191.532 | B30: bvanhorn@ucsd.edu | C30: A18513923 | D30: Brandon Van Horn | E30: https://drive.google.com/file/d/10WxTwUnnqZvct8veh3aSlAbwXnj-hVeW/view?usp=sharing | F30: 185.5 | G30: 3.9 | H30: I certify that I have completed the pre-requisites listed at https://datascience.ucsd.edu/current-students/course-descriptions-and-prerequisites/#dsc-180a-data-science-project-1 and I am eligible to enroll in DSC 180A. | I30: D03 | J30: D06 | K30: D05 | L30: D02 | M30: D01
A31: 46193.605 | B31: mpudukottaikrishnara@ucsd.edu | C31: A18266463 | D31: Madhav Pudukottai Krishnaraj | E31: https://drive.google.com/file/d/1YGTFSKAd4AJT0nfmu0tLvs6NGV3gu5x9/view?usp=sharing | F31: 177 | G31: 3.529 | H31: I certify that I have completed the pre-requisites listed at https://datascience.ucsd.edu/current-students/course-descriptions-and-prerequisites/#dsc-180a-data-science-project-1 and I am eligible to enroll in DSC 180A. | I31: D03 | J31: D02 | K31: D43 | L31: D10 | M31: D21 | N31: D28 | O31: D23 | P31: D34 | Q31: D37 | R31: D38
A32: 46192.934 | B32: vsahjwani@ucsd.edu | C32: A17785797 | D32: Vani Sahjwani | E32: https://drive.google.com/file/d/1puwnAM_58vKb6NZtUXO4_CvbSbExs9VU/view?usp=sharing | F32: 229 | G32: 3.56 | H32: I certify that I have completed the pre-requisites listed at https://datascience.ucsd.edu/current-students/course-descriptions-and-prerequisites/#dsc-180a-data-science-project-1 and I am eligible to enroll in DSC 180A. | I32: D04 | J32: D39 | K32: D40 | L32: D12 | M32: D17 | N32: D38
A33: 46192.549 | B33: kyzhao@ucsd.edu | C33: A18357580 | D33: Kyle Zhao | E33: https://drive.google.com/file/d/1QLFaezyIfe7B9rLdJWvKixn54HKjq-M7/view?usp=sharing | F33: 172 | G33: 3.88 | H33: I certify that I have completed the pre-requisites listed at https://datascience.ucsd.edu/current-students/course-descriptions-and-prerequisites/#dsc-180a-data-science-project-1 and I am eligible to enroll in DSC 180A. | I33: D04 | J33: D26 | K33: D01 | L33: D28 | M33: D31 | N33: D22 | O33: D30 | P33: D07 | Q33: D06 | R33: D12
A34: 46191.861 | B34: tap008@ucsd.edu | C34: A18345479 | D34: Taejun Park | E34: https://drive.google.com/file/d/1uPPxRcJwJ1dkPRRS-HmSzbJu1QbhFsRo/view?usp=sharing | F34: 142 | G34: 4 | H34: I certify that I have completed the pre-requisites listed at https://datascience.ucsd.edu/current-students/course-descriptions-and-prerequisites/#dsc-180a-data-science-project-1 and I am eligible to enroll in DSC 180A. | I34: D04 | J34: D34 | K34: D13 | L34: D38 | M34: D43 | N34: D36 | O34: D23 | P34: D18 | Q34: D10 | R34: D17
A35: 46192.975 | B35: mjviray@ucsd.edu | C35: A18520711 | D35: Matthew Justine Viray | E35: https://drive.google.com/file/d/1gBjkrqkGCxtq7dXULSf3nUU1lZ6F_XGV/view?usp=drive_link | F35: 217 | G35: 3.81 | H35: I certify that I have completed the pre-requisites listed at https://datascience.ucsd.edu/current-students/course-descriptions-and-prerequisites/#dsc-180a-data-science-project-1 and I am eligible to enroll in DSC 180A. | I35: D05 | J35: D19 | K35: D01 | L35: D11 | M35: D44 | N35: D42 | O35: D28 | P35: D23 | Q35: D21 | R35: D20
A36: 46194.992 | B36: stey@ucsd.edu | C36: A18566916 | D36: Sharon Tey | E36: https://docs.google.com/document/d/1k24uXGLmV4uhrT1QkVirIt3kmlx5FcFwgg1R_6KuIiA/edit?usp=sharing | F36: 99 | G36: 3.73 | H36: I certify that I have completed the pre-requisites listed at https://datascience.ucsd.edu/current-students/course-descriptions-and-prerequisites/#dsc-180a-data-science-project-1 and I am eligible to enroll in DSC 180A. | I36: D05 | J36: D44 | K36: D01 | L36: D28 | M36: D37 | N36: D36 | O36: D34 | P36: D10 | Q36: D17 | R36: D08
A37: 46195.854 | B37: anellis@ucsd.edu | C37: A17830583 | D37: Annaly Ellis | E37: https://drive.google.com/file/d/1Y5A4OFBKCxFlLPyo0ruloo-LGRSTx6Em/view?usp=sharing | F37: 193 | G37: 3.652 | H37: I certify that I have completed the pre-requisites listed at https://datascience.ucsd.edu/current-students/course-descriptions-and-prerequisites/#dsc-180a-data-science-project-1 and I am eligible to enroll in DSC 180A. | I37: D06 | J37: D01 | K37: D14 | L37: D38 | M37: D12 | N37: D23 | O37: D26 | P37: D37 | Q37: D02 | R37: D16
A38: 46191.634 | B38: manissen@ucsd.edu | C38: A17961729 | D38: Margot Nissen | E38: https://docs.google.com/document/d/1W9v64R68TtvkJfMuidwXZrzokJpL7X4Wotn5Y1tDkJI/edit?usp=sharing | F38: 200 | G38: 3.48 | H38: I certify that I have completed the pre-requisites listed at https://datascience.ucsd.edu/current-students/course-descriptions-and-prerequisites/#dsc-180a-data-science-project-1 and I am eligible to enroll in DSC 180A. | I38: D07 | J38: D43 | K38: D08 | L38: D42 | M38: D18 | N38: D05 | O38: D03 | P38: D16 | Q38: D01 | R38: D15
A39: 46194.6 | B39: japarra@ucsd.edu | C39: A17939771 | D39: Jared Parra | E39: https://docs.google.com/document/d/e/2PACX-1vSMNhW1qSDbxh_4CXTtjR40Z9fMcRjp6qk97OcjX6bbuio0XqG-c87IdychjfGeB1vCLaB8CSxlUO0Z/pub | F39: 196.75 | G39: 3.113 | H39: I certify that I have completed the pre-requisites listed at https://datascience.ucsd.edu/current-students/course-descriptions-and-prerequisites/#dsc-180a-data-science-project-1 and I am eligible to enroll in DSC 180A. | I39: D07 | J39: D12 | K39: D42 | L39: D08 | M39: D01 | N39: D23 | O39: D24 | P39: D05 | Q39: D14 | R39: D15
A40: 46195.951 | B40: amuhamadafandy@ucsd.edu | C40: A17372335 | D40: Amjad Faiz Bin Muhamad Afandy | E40: https://drive.google.com/file/d/1GA8EDhBNr6SSygTDg9k4IjukUyiXfViD/view?usp=sharing | F40: 170 | G40: 3.132 | H40: I certify that I have completed the pre-requisites listed at https://datascience.ucsd.edu/current-students/course-descriptions-and-prerequisites/#dsc-180a-data-science-project-1 and I am eligible to enroll in DSC 180A. | I40: D07 | J40: D08 | K40: D01 | L40: D42 | M40: D15
...

Sheet Mentor Choices
A1: Domain ID | B1: Mentors | C1: Capacity | D1: Student 1 | E1: Student 2 | F1: Student 3 | G1: Student 4 | H1: Student 5 | I1: Student 6 | J1: Student 7 | K1: Student 8 | L1: Student 9 | M1: Student 10 | N1: Student 11 | O1: Student 12
A2: D01 | B2: Ali Arsanjani | C2: 16
A3: D02 | B3: Aobo Li | C3: 5
A4: D03 | B4: Ben Smarr | C4: 4 | D4: A18592255 | E4: A17719081 | F4: A18513923 | G4: A17887951
A5: D04 | B5: Biwei Huang | C5: 8
A6: D05 | B6: Haojian Jin | C6: 12 | D6: A18566916 | E6: A18513923 | F6: A17886164 | G6: A18520711 | H6: A17853531 | I6: A17817280 | J6: A18542060 | K6: A18114647 | L6: A18113461 | M6: A18485962 | N6: A18112290 | O6: A17950464
A7: D06 | B7: Duncan Watson-Parris | C7: 8
A8: D07 | B8: Emily Aiken | C8: 6
A9: D08 | B9: Gabriel Garzo | C9: 8 | D9: A18505526 | E9: A18111807 | F9: A17718801 | G9: A18539554 | H9: A18609679 | I9: A18590715 | J9: A17855583 | K9: A17870464 | L9: A18605782 | M9: A18113311 | N9: A17920154 | O9: A17817145
A10: D09 | B10: Igor Sfiligoi | C10: 8 | D10: A18523157 | E10: A17912246 | F10: A18633375 | G10: A18321535 | H10: A19081559 | I10: A17853057 | J10: A17758046 | K10: A17886164 | L10: A18603940 | M10: A17787465 | N10: A17930477 | O10: A18616536
A11: D10 | B11: Igor Sfiligoi | C11: 8 | D11: A18603940 | E11: A18523157 | F11: A17987465 | G11: A17886164 | H11: A17711319 | I11: A18321535 | J11: A18554338 | K11: A18504223 | L11: A18112670 | M11: A17784761 | N11: A17929245 | O11: A17832678
A12: D11 | B12: Ilyes Meftah | C12: 8
A13: D12 | B13: Kyle Nero | C13: 12 | D13: A17768490 | E13: A18030348 | F13: A18127466 | G13: A18386039 | H13: A18116163 | I13: A17736930 | J13: A17810860 | K13: A16803192 | L13: A18529982 | M13: A17944500 | N13: A17949683 | O13: A17802231 | P13: A18247795 | Q13: A18592255
A14: D13 | B14: Mikio Aoi | C14: 8
A15: D14 | B15: Nathan Hui | C15: 5 | D15: A17869683 | E15: A17830583 | F15: A18115996 | G15: A17918188 | H15: A18113345 | I15: A17906305
A16: D15 | B16: Rayan Saab | C16: 7 | D16: A18112714 | E16: A18565063 | F16: A17710650 | G16: A18112703 | H16: A17842934 | I16: A17847114 | J16: A17929245
A17: D16 | B17: Rob Knight | C17: 8
A18: D17 | B18: Tauhidur Rahaman | C18: 8
A19: D18 | B19: Tiffany Amariuta | C19: 8 | D19: A17864314 | E19: A17475690 | F19: A18111889 | G19: A18523157 | H19: A18524674 | I19: A17987465
A20: D19 | B20: Victor Minces | C20: 6 | D20: A17880443 | E20: A17794419 | F20: A18552753 | G20: A17991929 | H20: A17906305 | I20: A18237194 | J20: A19190519
A21: D20 | B21: Alex Warstadt | C21: 6 | D21: A18113461 | E21: A17847578 | F21: A17860402 | G21: A17860402 | H21: A17772507 | I21: A18111272 | J21: A17813712 | K21: A17728266 | L21: A17784010 | M21: A17947443 | N21: A17807608 | O21: A18113311 | P21: A17920154
A22: D21 | B22: Armin Schwartzman | C22: 16 | D22: A18121534 | E22: A17906173 | F22: A17800006 | G22: A17781241 | H22: A18423915 | I22: A18555408 | J22: A17799160 | K22: A18485962 | L22: A18111272 | M22: A18520437 | N22: A17813712 | O22: A17827322 | P22: A17994070 | Q22: A18575891 | R22: A17911498 | S22: A17710282
A23: D22 | B23: Dmitriy Drusvyatskiy | C23: 0
A24: D23 | B24: Dusan Bosnjakovic | C24: 4 | D24: A18552804 | E24: A17855615 | F24: A17785865 | G24: A17858150
A25: D24 | B25: Haojian Jin | C25: 0
A26: D25 | B26: Jingbo Shang | C26: 4 | D26: A18113535 | E26: A18506253 | F26: A17921209 | G26: A17837620
A27: D26 | B27: Lily Weng | C27: 8
A28: D27 | B28: Misha Belkin | C28: 10
A29: D28 | B29: Ryan Lingo | C29: 12 | D29: A17903894 | E29: A17817280 | F29: A17884008 | G29: A17785865 | H29: A17960283 | I29: A17918188 | J29: A18562193 | K29: A18606977 | L29: A17836503 | M29: A19172216 | N29: A17807608 | O29: A17704905
A30: D29 | B30: Stuart Geiger | C30: 6
A31: D30 | B31: Tianhao Wang | C31: 8 | D31: A18235912 | E31: A17920946 | F31: A17919813 | G31: A18536011 | H31: A17874686 | I31: A17848067 | J31: A17715152 | K31: A17713463 | L31: A17816744 | M31: A17713463 | N31: A17785865 | O31: A18357580
A32: D31 | B32: Yoav Freund | C32: 4 | D32: A18585872 | E32: A18251274 | F32: A18219465 | G32: A18112290 | H32: A18282418 | I32: A17947443 | J32: A18555408
A33: D32 | B33: Yusu Wang | C33: 12
A34: D33 | B34: Babak Salimi | C34: 4 | D34: A17874686 | E34: A17922611 | F34: A18598144 | G34: A17713463 | H34: A17771842 | I34: A17798100
A35: D34 | B35: Hao Zhang | C35: 6
A36: D35 | B36: Rajesh Gupta | C36: 4
A37: D36 | B37: Renu Raman | C37: 4 | D37: A18603940 | E37: A17843999 | F37: A18566916 | G37: A17966871 | H37: A18546099 | I37: A18609679
A38: D37 | B38: Renu Raman | C38: 6 | D38: A17817280 | E38: A17735225 | F38: A18321535 | G38: A17747801 | H38: A17848688 | I38: A18112670 | J38: A18279028 | K38: A17884008 | L38: A17889532 | M38: A18565063
A39: D38 | B39: Zhijian Liu | C39: 8 | D39: A17855312 | E39: A18510359 | F39: A18114180 | G39: A18598144 | H39: A18110131 | I39: A17948928 | J39: A17957434 | K39: A18231714 | L39: A18235912 | M39: A17976167 | N39: A17787465 | O39: A17784761
A40: D39 | B40: Arya Mazumdar | C40: 8
...

Sheet bydomain
A1: Domain ID | B1: Capacity | C1: Allocated | D1: Spares | E1: Mentor | F1: Students
A2: D01 | B2: 16 | C2: 16 | D2: =B2-C2 -> 0 | F2: Akshitaa Balasai, April Huang, Bobby Zhou, Derek Kuang, Ethan Lam, Grace Trainor, Hannah Gonzalez, Janice Rincon, Jordi Pham, Kyle Flores, Rezon Gautama, Saanvi Ranadive, Susana Haing, Vanessa Lau, Zachary Loo, Sonali Singh
A3: D02 | B3: 5 | C3: =IFERROR(__xludf.DUMMYFUNCTION("IF(F3="""", 0, COUNTA(SPLIT(F3, "","")))"),5.0) -> 5 | D3: =B3-C3 -> 0 | F3: Bryan Cruz, Hieu Nguyen, Madhav Pudukottai Krishnaraj, Ryan Conrad Atienza, Timothy Harmon
A4: D03 | B4: 4 | C4: =IFERROR(__xludf.DUMMYFUNCTION("IF(F4="""", 0, COUNTA(SPLIT(F4, "","")))"),4.0) -> 4 | D4: =B4-C4 -> 0 | F4: Alisha Wang, Brandon Van Horn, Matthew Vaught, Vivian Lin
A5: D04 | B5: 8 | C5: =IFERROR(__xludf.DUMMYFUNCTION("IF(F5="""", 0, COUNTA(SPLIT(F5, "","")))"),8.0) -> 8 | D5: =B5-C5 -> 0 | F5: Bryan Nguyen, Joey Sandoval, Juee Deshmukh, Kyle Zhao, Palina Volskaya, Scarlett Scott, Uzair Gheewala, Vani Sahjwani
A6: D05 | B6: 12 | C6: =IFERROR(__xludf.DUMMYFUNCTION("IF(F6="""", 0, COUNTA(SPLIT(F6, "","")))"),12.0) -> 12 | D6: =B6-C6 -> 0 | F6: Ali Ahmed, Claire Lee, Daniel Huang, David Chew, Jared Parra, Justin Lee, Keanu Ventura, Lillian Tran, Marvell Suhali, Matthew Justine Viray, Ryan Lee, Sharon Tey
A7: D06 | B7: 8 | C7: =IFERROR(__xludf.DUMMYFUNCTION("IF(F7="""", 0, COUNTA(SPLIT(F7, "","")))"),8.0) -> 8 | D7: =B7-C7 -> 0 | F7: Annaly Ellis, Cheryl Xiang, Coleman Clougherty, Coltrane Gowan, Jennifer Chang, Linus Lee, Roman Respicio, Vishal Rana Paidi
A8: D07 | B8: 6 | C8: =IFERROR(__xludf.DUMMYFUNCTION("IF(F8="""", 0, COUNTA(SPLIT(F8, "","")))"),6.0) -> 6 | D8: =B8-C8 -> 0 | F8: Margot Nissen, Maya Sissel, Mieko Chun, Prisha Maiti, Simone Rao, Su Love Wai
A9: D08 | B9: 8 | C9: =IFERROR(__xludf.DUMMYFUNCTION("IF(F9="""", 0, COUNTA(SPLIT(F9, "","")))"),8.0) -> 8 | D9: =B9-C9 -> 0 | F9: Audrey Chung, Gabriel Maayah, Kang Lee, Kate Feng, Keilani Li, Siya Sathaye, Tiantian Zheng, Tristan Leo
A10: D09 | B10: 8 | C10: =IFERROR(__xludf.DUMMYFUNCTION("IF(F10="""", 0, COUNTA(SPLIT(F10, "","")))"),8.0) -> 8 | D10: =B10-C10 -> 0 | F10: Ahmad Ageel, Dariy Marshaev, Dylan Vo, Junle Li, Khaleel Karim, Marcelo Arcos, Rohan Raval, Zonglin Zhang
A11: D10 | B11: 8 | C11: =IFERROR(__xludf.DUMMYFUNCTION("IF(F11="""", 0, COUNTA(SPLIT(F11, "","")))"),7.0) -> 7 | D11: =B11-C11 -> 1 | F11: Aryan Nath, Jaden Goelkel, Jay Manjrekar, Joseph Calderon, Ketan Mittal, Ryan Lindberg, Sweekrit Bhatnagar
A12: D11 | B12: 8 | C12: =IFERROR(__xludf.DUMMYFUNCTION("IF(F12="""", 0, COUNTA(SPLIT(F12, "","")))"),8.0) -> 8 | D12: =B12-C12 -> 0 | F12: Aarshia Gupta, Clayton Tan, Dhruv Sehgal, Dylan Louie, Emily Yip, Erika Tong, Kaushik Agastyaraju, Yutao Lin
A13: D12 | B13: 12 | C13: =IFERROR(__xludf.DUMMYFUNCTION("IF(F13="""", 0, COUNTA(SPLIT(F13, "","")))"),12.0) -> 12 | D13: =B13-C13 -> 0 | F13: Aiden Lai, Huiyu Yie, Ishaan Tibdewal, Jack Ding, Katie Hannigan, Liuxuhong Zhao, Michael Petersen, Sam Ouyang, Song Su, Steven Ouyang, Vanessa Feng, Zilig Xu
A14: D13 | B14: 8 | C14: 8 | D14: =B14-C14 -> 0 | F14: Antony Munkhchuluun, Audrey Meredith, Hansel Puthenparambil, Kevin Zhu, Lyn Mansfield, Matthew Lee, Taejun Park, Trinity Truong
A15: D14 | B15: 5 | C15: =IFERROR(__xludf.DUMMYFUNCTION("IF(F15="""", 0, COUNTA(SPLIT(F15, "","")))"),5.0) -> 5 | D15: =B15-C15 -> 0 | F15: Elvin Chen, Jocelyn Miao, Munachimso Ndubisi, Rocio Saez Aguirre, Summer Garvais
A16: D15 | B16: 8 | C16: =IFERROR(__xludf.DUMMYFUNCTION("IF(F16="""", 0, COUNTA(SPLIT(F16, "","")))"),8.0) -> 8 | D16: =B16-C16 -> 0 | F16: Aarav Agrawal, Adrian Kong, Chidiebere Agunanne, Owen McFadden, Siddhartha Sarvepally, Ty Albao, Zach Cochran, Dylan Cheng
A17: D16 | B17: 8 | C17: =IFERROR(__xludf.DUMMYFUNCTION("IF(F17="""", 0, COUNTA(SPLIT(F17, "","")))"),7.0) -> 7 | D17: =B17-C17 -> 1 | F17: Claire Wang, Jonathan Yepez, Junran Yang, Nicholas Chan, Ruofei Mao, Sahana Rangan, Terran Chow
A18: D17 | B18: 8 | C18: 9 | D18: =B18-C18 -> -1 | F18: Bryan Zhang, Cheng-I Lin, Claire Tu, Colin Tran, Haoshuo Bi, Jacob Doan, Jeremy Cho, Yi-Hsuan Kuo, Po-Chen Lin
A19: D18 | B19: 8 | C19: =IFERROR(__xludf.DUMMYFUNCTION("IF(F19="""", 0, COUNTA(SPLIT(F19, "","")))"),8.0) -> 8 | D19: =B19-C19 -> 0 | F19: Abdulrahim Ham, Borngreat Omoma-Edosa, Grace Chen, Jared Wang, Krish Desai, Sana Gupta, Tori Nguyen, Ziyan Liu
A20: D19 | B20: 6 | C20: =IFERROR(__xludf.DUMMYFUNCTION("IF(F20="""", 0, COUNTA(SPLIT(F20, "","")))"),6.0) -> 6 | D20: =B20-C20 -> 0 | F20: Acelynn Qiao, Leonard Malott, Minyoung Kim, Sahar Zahir, Viela Lansangan, Yadushan Thillainathan
A21: D20 | B21: 6 | C21: =IFERROR(__xludf.DUMMYFUNCTION("IF(F21="""", 0, COUNTA(SPLIT(F21, "","")))"),5.0) -> 5 | D21: =B21-C21 -> 1 | F21: Esther Chung, Jason Liu, Karthik Sankaran, Michelle Hong, Samson Wan
A22: D21 | B22: 16 | C22: =IFERROR(__xludf.DUMMYFUNCTION("IF(F22="""", 0, COUNTA(SPLIT(F22, "","")))"),16.0) -> 16 | D22: =B22-C22 -> 0 | F22: Abhi Sathvika Goriparthy, Alex Frederick, Atherv Vidhate, Gavin Wu, Genevieve Selsor, Jeremy Cheng, Jonathan Yim, Kimi Chen, Pranav Rajaram, Preethi Manne, Terry Su, Tony Bai, Vincent Cho, Xiao Cheng, Yidong Shi, Zubin Sannakkayala
A23: D22 | B23: 0 | C23: =IFERROR(__xludf.DUMMYFUNCTION("IF(F23="""", 0, COUNTA(SPLIT(F23, "","")))"),0.0) -> 0 | D23: =B23-C23 -> 0
A24: D23 | B24: 4 | C24: =IFERROR(__xludf.DUMMYFUNCTION("IF(F24="""", 0, COUNTA(SPLIT(F24, "","")))"),4.0) -> 4 | D24: =B24-C24 -> 0 | F24: Ishaan Gosain, Ivan Chen, Jiya Makhija, Sophia Vo
A25: D24 | B25: 0 | C25: =IFERROR(__xludf.DUMMYFUNCTION("IF(F25="""", 0, COUNTA(SPLIT(F25, "","")))"),0.0) -> 0 | D25: =B25-C25 -> 0
A26: D25 | B26: 4 | C26: =IFERROR(__xludf.DUMMYFUNCTION("IF(F26="""", 0, COUNTA(SPLIT(F26, "","")))"),5.0) -> 5 | D26: =B26-C26 -> -1 | F26: Akshay Uppal, Edwards Tong, Kangxin Peng, Yonghao Wang, Jingwen Gu
A27: D26 | B27: 8 | C27: =IFERROR(__xludf.DUMMYFUNCTION("IF(F27="""", 0, COUNTA(SPLIT(F27, "","")))"),8.0) -> 8 | D27: =B27-C27 -> 0 | F27: Amrutha Potluri, Dylan Craver, Dylan Dsouza, Julia Dial, Keith Gong, Pratham Aggarwal, Ritvik Chand, Zhuang Mingrui
A28: D27 | B28: 10 | C28: =IFERROR(__xludf.DUMMYFUNCTION("IF(F28="""", 0, COUNTA(SPLIT(F28, "","")))"),10.0) -> 10 | D28: =B28-C28 -> 0 | F28: Amjad Faiz Bin Muhamad Afandy, Flavia Gabriella Tedjarutjianta, Gabriel Tedja, Hasaam Butt, Janie Chan, Mohak Prakash, Prabhjas Singh, Qi Zhang, Shunyi Du, Sonali Singh
A29: D28 | B29: 12 | C29: =IFERROR(__xludf.DUMMYFUNCTION("IF(F29="""", 0, COUNTA(SPLIT(F29, "","")))"),12.0) -> 12 | D29: =B29-C29 -> 0 | F29: Aarushi Jain, Brian Jing, Chinmay Bharambe, Daniel Budidharma, Henry Liu, Katie Moc, Raghav Dewangan, Royce Nguyen, Ryan Tang, Shawn Cheng, Turki Alrasheed, Viki Shi
A30: D29 | B30: 6 | C30: =IFERROR(__xludf.DUMMYFUNCTION("IF(F30="""", 0, COUNTA(SPLIT(F30, "","")))"),6.0) -> 6 | D30: =B30-C30 -> 0 | F30: Amelia Wong, Arushi Patra, Mythri Kishore, Nayana Naineni, Sumedha Rai, Vanshika Somani
A31: D30 | B31: 8 | C31: =IFERROR(__xludf.DUMMYFUNCTION("IF(F31="""", 0, COUNTA(SPLIT(F31, "","")))"),8.0) -> 8 | D31: =B31-C31 -> 0 | F31: Alexander Kuo, Daniel Phan, Edison Ayran, Fiona Zou, Jiahe Qin, Praveen Sharma, Terence Zhang, Wanchen Yang
A32: D31 | B32: 4 | C32: =IFERROR(__xludf.DUMMYFUNCTION("IF(F32="""", 0, COUNTA(SPLIT(F32, "","")))"),4.0) -> 4 | D32: =B32-C32 -> 0 | F32: Andrew Chen, Saisohan Shingade, Surya Setty, Uday Lingampalli
A33: D32 | B33: 12 | C33: =IFERROR(__xludf.DUMMYFUNCTION("IF(F33="""", 0, COUNTA(SPLIT(F33, "","")))"),13.0) -> 13 | D33: =B33-C33 -> -1 | F33: Aathi Muthu, Anand Baidya, Andrew Youn, Brian Can, Haowen Zhang, Jaden Vo, Nimisha Mishra, Po-Hua Chen, Shiv Mehta, Vedant Vardhaan, Vishudh Shah, Zhixiang Zhang, Evelyn Zhang
A34: D33 | B34: 8 | C34: 8 | D34: =B34-C34 -> 0 | F34: Divyansh Kanodia, Kavyan Patel, Kevin Zhang, Ved Panse, Noah Golder, Michael Luo, Ananya Wasker, Vipra Bindal
A35: D34 | B35: 0 | C35: =IFERROR(__xludf.DUMMYFUNCTION("IF(F35="""", 0, COUNTA(SPLIT(F35, "","")))"),0.0) -> 0 | D35: =B35-C35 -> 0
A36: D35 | B36: 4 | C36: =IFERROR(__xludf.DUMMYFUNCTION("IF(F36="""", 0, COUNTA(SPLIT(F36, "","")))"),4.0) -> 4 | D36: =B36-C36 -> 0 | F36: Leo Wiemelt, Lucien Hsiao, Neil Dewan, Zihan Zhang
A37: D36 | B37: 4 | C37: =IFERROR(__xludf.DUMMYFUNCTION("IF(F37="""", 0, COUNTA(SPLIT(F37, "","")))"),4.0) -> 4 | D37: =B37-C37 -> 0 | F37: Casey So, Mehul Verma, Rakshan Patnaik, Tejas Mani
A38: D37 | B38: 6 | C38: =IFERROR(__xludf.DUMMYFUNCTION("IF(F38="""", 0, COUNTA(SPLIT(F38, "","")))"),6.0) -> 6 | D38: =B38-C38 -> 0 | F38: Deepal Deleena, Jacob Kavanal, Lakshmi Manasa Maddi, Mianzhi Hu, Vaidehi Karve, Victor Chen
A39: D38 | B39: 8 | C39: =IFERROR(__xludf.DUMMYFUNCTION("IF(F39="""", 0, COUNTA(SPLIT(F39, "","")))"),10.0) -> 10 | D39: =B39-C39 -> -2 | F39: Alan Xia, Alexander Takamoto, Brian Liu, Edward Zhang, Issac Roy, Maggie Zhang, Philip Chen, Yash Tandon, Chentao Gong, Anirudh Annabathula
A40: D39 | B40: 8 | C40: =IFERROR(__xludf.DUMMYFUNCTION("IF(F40="""", 0, COUNTA(SPLIT(F40, "","")))"),8.0) -> 8 | D40: =B40-C40 -> 0 | F40: Abhinav Chinnam, Ganesh Kumarappan, Jayden Li, Kenji Gunawan, Nuraiym Mirbekova, Raffi Dulgerian, Rishvik Ravi, Aditya Kakarla
...

Sheet bystudent
A1: PID | B1: TSN | C1: Name | D1: Email | E1: Domain ID | F1: Mentor | G1: Whether Enrolled
A2: A17372335 | B2: {=index(PIDtoTSN!E:E, match(A2, PIDtoTSN!A:A, 0))} -> 200224596 | C2: Amjad Faiz Bin Muhamad Afandy | D2: amuhamadafandy@ucsd.edu | E2: D27 | F2: {=index('Mentor Choices'!B:B, match(E2, 'Mentor Choices'!A:A, 0))} -> Misha Belkin | G2: =IF(COUNTIF(Sept16!C:C, B2) > 0, "yes", "no") -> no
A3: A17475690 | B3: {=index(PIDtoTSN!E:E, match(A3, PIDtoTSN!A:A, 0))} -> 200212751 | C3: Grace Chen | D3: gmc001@ucsd.edu | E3: D18 | F3: {=index('Mentor Choices'!B:B, match(E3, 'Mentor Choices'!A:A, 0))} -> Tiffany Amariuta | G3: =IF(COUNTIF(Sept16!C:C, B3) > 0, "yes", "no") -> no
A4: A17709547 | B4: {=index(PIDtoTSN!E:E, match(A4, PIDtoTSN!A:A, 0))} -> 200183812 | C4: Matthew Lee | D4: mal060@ucsd.edu | E4: D13 | F4: {=index('Mentor Choices'!B:B, match(E4, 'Mentor Choices'!A:A, 0))} -> Mikio Aoi | G4: =IF(COUNTIF(Sept16!C:C, B4) > 0, "yes", "no") -> no
A5: A17710650 | B5: {=index(PIDtoTSN!E:E, match(A5, PIDtoTSN!A:A, 0))} -> 200183972 | C5: Zach Cochran | D5: zcochran@ucsd.edu | E5: D15 | F5: {=index('Mentor Choices'!B:B, match(E5, 'Mentor Choices'!A:A, 0))} -> Rayan Saab | G5: =IF(COUNTIF(Sept16!C:C, B5) > 0, "yes", "no") -> no
A6: A17768490 | B6: {=index(PIDtoTSN!E:E, match(A6, PIDtoTSN!A:A, 0))} -> 200173831 | C6: Song Su | D6: sosu@ucsd.edu | E6: D12 | F6: {=index('Mentor Choices'!B:B, match(E6, 'Mentor Choices'!A:A, 0))} -> Kyle Nero | G6: =IF(COUNTIF(Sept16!C:C, B6) > 0, "yes", "no") -> no
A7: A17900594 | B7: {=index(PIDtoTSN!E:E, match(A7, PIDtoTSN!A:A, 0))} -> 200150496 | C7: Bryan Zhang | D7: brzhang@ucsd.edu | E7: D17 | F7: {=index('Mentor Choices'!B:B, match(E7, 'Mentor Choices'!A:A, 0))} -> Tauhidur Rahaman | G7: =IF(COUNTIF(Sept16!C:C, B7) > 0, "yes", "no") -> no
A8: A17912246 | B8: {=index(PIDtoTSN!E:E, match(A8, PIDtoTSN!A:A, 0))} -> 200152388 | C8: Marcelo Arcos | D8: marcos@ucsd.edu | E8: D09 | F8: {=index('Mentor Choices'!B:B, match(E8, 'Mentor Choices'!A:A, 0))} -> Igor Sfiligoi | G8: =IF(COUNTIF(Sept16!C:C, B8) > 0, "yes", "no") -> no
A9: A18251274 | B9: {=index(PIDtoTSN!E:E, match(A9, PIDtoTSN!A:A, 0))} -> 200092842 | C9: Timothy Harmon | D9: t2harmon@ucsd.edu | E9: D02 | F9: {=index('Mentor Choices'!B:B, match(E9, 'Mentor Choices'!A:A, 0))} -> Aobo Li | G9: =IF(COUNTIF(Sept16!C:C, B9) > 0, "yes", "no") -> no
A10: A18274026 | B10: {=index(PIDtoTSN!E:E, match(A10, PIDtoTSN!A:A, 0))} -> 200089500 | C10: Krish Desai | D10: ksdesai@ucsd.edu | E10: D18 | F10: {=index('Mentor Choices'!B:B, match(E10, 'Mentor Choices'!A:A, 0))} -> Tiffany Amariuta | G10: =IF(COUNTIF(Sept16!C:C, B10) > 0, "yes", "no") -> no
A11: A18509617 | B11: {=index(PIDtoTSN!E:E, match(A11, PIDtoTSN!A:A, 0))} -> 200052943 | C11: Marvell Suhali | D11: msuhali@ucsd.edu | E11: D05 | F11: {=index('Mentor Choices'!B:B, match(E11, 'Mentor Choices'!A:A, 0))} -> Haojian Jin | G11: =IF(COUNTIF(Sept16!C:C, B11) > 0, "yes", "no") -> no
A12: A18521431 | B12: {=index(PIDtoTSN!E:E, match(A12, PIDtoTSN!A:A, 0))} -> 200048174 | C12: Claire Tu | D12: c7tu@ucsd.edu | E12: D17 | F12: {=index('Mentor Choices'!B:B, match(E12, 'Mentor Choices'!A:A, 0))} -> Tauhidur Rahaman | G12: =IF(COUNTIF(Sept16!C:C, B12) > 0, "yes", "no") -> no
A13: A18548215 | B13: {=index(PIDtoTSN!E:E, match(A13, PIDtoTSN!A:A, 0))} -> 200046453 | C13: Rose Park | D13: sep032@ucsd.edu | E13: D41 | F13: {=index('Mentor Choices'!B:B, match(E13, 'Mentor Choices'!A:A, 0))} -> Peter Chi | G13: =IF(COUNTIF(Sept16!C:C, B13) > 0, "yes", "no") -> no
... A15: A18639524 | B15: {=index(PIDtoTSN!E:E, match(A15, PIDtoTSN!A:A, 0))} -> 200021549 | C15: Rishvik Ravi | D15: r4ravi@ucsd.edu | E15: D39 | F15: {=index('Mentor Choices'!B:B, match(E15, 'Mentor Choices'!A:A, 0))} -> Arya Mazumdar | G15: =IF(COUNTIF(Sept16!C:C, B15) > 0, "yes", "no") -> no
B16: 200024478 | C16: Vipra Bindal | D16: vbindal@ucsd.edu | E16: D33 | F16: {=index('Mentor Choices'!B:B, match(E16, 'Mentor Choices'!A:A, 0))} -> Babak Salimi | G16: =IF(COUNTIF(Sept16!C:C, B16) > 0, "yes", "no") -> no
A17: A17710282 | B17: {=index(PIDtoTSN!E:E, match(A17, PIDtoTSN!A:A, 0))} -> 200183921 | C17: Antony Munkhchuluun | D17: emunkhchuluun@ucsd.edu | E17: D13 | F17: {=index('Mentor Choices'!B:B, match(E17, 'Mentor Choices'!A:A, 0))} -> Mikio Aoi | G17: =IF(COUNTIF(Sept16!C:C, B17) > 0, "yes", "no") -> no
A18: A17919813 | B18: {=index(PIDtoTSN!E:E, match(A18, PIDtoTSN!A:A, 0))} -> 200147555 | C18: Praveen Sharma | D18: p4sharma@ucsd.edu | E18: D30 | F18: {=index('Mentor Choices'!B:B, match(E18, 'Mentor Choices'!A:A, 0))} -> Tianhao Wang | G18: =IF(COUNTIF(Sept16!C:C, B18) > 0, "yes", "no") -> no
A19: A17922611 | B19: {=index(PIDtoTSN!E:E, match(A19, PIDtoTSN!A:A, 0))} -> 200147889 | C19: Divyansh Kanodia | D19: dkanodia@ucsd.edu | E19: D33 | F19: {=index('Mentor Choices'!B:B, match(E19, 'Mentor Choices'!A:A, 0))} -> Babak Salimi | G19: =IF(COUNTIF(Sept16!C:C, B19) > 0, "yes", "no") -> no
A20: A17948928 | B20: {=index(PIDtoTSN!E:E, match(A20, PIDtoTSN!A:A, 0))} -> 200144995 | C20: Yash Tandon | D20: ytandon@ucsd.edu | E20: D38 | F20: {=index('Mentor Choices'!B:B, match(E20, 'Mentor Choices'!A:A, 0))} -> Zhijian Liu | G20: =IF(COUNTIF(Sept16!C:C, B20) > 0, "yes", "no") -> no
A21: A18110768 | B21: {=index(PIDtoTSN!E:E, match(A21, PIDtoTSN!A:A, 0))} -> 200121619 | C21: Amy Zhao | D21: amz004@ucsd.edu | E21: D43 | F21: {=index('Mentor Choices'!B:B, match(E21, 'Mentor Choices'!A:A, 0))} -> Reem Khojah | G21: =IF(COUNTIF(Sept16!C:C, B21) > 0, "yes", "no") -> no
A22: A18585872 | B22: {=index(PIDtoTSN!E:E, match(A22, PIDtoTSN!A:A, 0))} -> 200032924 | C22: Saisohan Shingade | D22: sshingade@ucsd.edu | E22: D31 | F22: {=index('Mentor Choices'!B:B, match(E22, 'Mentor Choices'!A:A, 0))} -> Yoav Freund | G22: =IF(COUNTIF(Sept16!C:C, B22) > 0, "yes", "no") -> no
A23: A17886164 | B23: {=index(PIDtoTSN!E:E, match(A23, PIDtoTSN!A:A, 0))} -> 200154571 | C23: Ryan Tjenalooi | D23: rtjenalooi@ucsd.edu | F23: {=index('Mentor Choices'!B:B, match(E23, 'Mentor Choices'!A:A, 0))} -> #N/A | G23: WILL NOT ENROLL
A24: A18279028 | B24: {=index(PIDtoTSN!E:E, match(A24, PIDtoTSN!A:A, 0))} -> 200090248 | C24: Mianzhi Hu | D24: mih037@ucsd.edu | F24: {=index('Mentor Choices'!B:B, match(E24, 'Mentor Choices'!A:A, 0))} -> #N/A | G24: WILL NOT ENROLL
A25: A18584973 | B25: {=index(PIDtoTSN!E:E, match(A25, PIDtoTSN!A:A, 0))} -> 200032724 | C25: Moniriddh Bunyay | D25: mbunyay@ucsd.edu | F25: {=index('Mentor Choices'!B:B, match(E25, 'Mentor Choices'!A:A, 0))} -> #N/A | G25: WILL NOT ENROLL
A26: A19160671 | B26: {=index(PIDtoTSN!E:E, match(A26, PIDtoTSN!A:A, 0))} -> 200330225 | C26: Nuraiym Mirbekova | D26: nmirbekova@ucsd.edu | F26: {=index('Mentor Choices'!B:B, match(E26, 'Mentor Choices'!A:A, 0))} -> #N/A | G26: WILL NOT ENROLL
A27: A17814224 | B27: 200168572 | C27: Vishudh Shah | D27: v8shah@ucsd.edu | E27: D32 | F27: {=index('Mentor Choices'!B:B, match(E27, 'Mentor Choices'!A:A, 0))} -> Yusu Wang | G27: =IF(COUNTIF(Sept16!C:C, B27) > 0, "yes", "no") -> yes
A28: A17836503 | B28: 200165827 | C28: Henry Liu | D28: hel044@ucsd.edu | E28: D28 | F28: {=index('Mentor Choices'!B:B, match(E28, 'Mentor Choices'!A:A, 0))} -> Ryan Lingo | G28: =IF(COUNTIF(Sept16!C:C, B28) > 0, "yes", "no") -> yes
A29: A17944500 | B29: {=index(PIDtoTSN!E:E, match(A29, PIDtoTSN!A:A, 0))} -> 200144405 | C29: Steven Ouyang | D29: houyang@ucsd.edu | E29: D12 | F29: {=index('Mentor Choices'!B:B, match(E29, 'Mentor Choices'!A:A, 0))} -> Kyle Nero | G29: =IF(COUNTIF(Sept16!C:C, B29) > 0, "yes", "no") -> yes
A30: A17998422 | B30: 200137537 | C30: Kenji Gunawan | D30: kegunawan@ucsd.edu | E30: D39 | F30: {=index('Mentor Choices'!B:B, match(E30, 'Mentor Choices'!A:A, 0))} -> Arya Mazumdar | G30: =IF(COUNTIF(Sept16!C:C, B30) > 0, "yes", "no") -> yes
A31: A18116163 | B31: {=index(PIDtoTSN!E:E, match(A31, PIDtoTSN!A:A, 0))} -> 200114926 | C31: Vanessa Feng | D31: l6feng@ucsd.edu | E31: D12 | F31: {=index('Mentor Choices'!B:B, match(E31, 'Mentor Choices'!A:A, 0))} -> Kyle Nero | G31: =IF(COUNTIF(Sept16!C:C, B31) > 0, "yes", "no") -> yes
A32: A18131111 | B32: 200117610 | C32: Evelyn Zhang | D32: yuz271@ucsd.edu | E32: D32 | F32: Yusu Wang | G32: =IF(COUNTIF(Sept16!C:C, B32) > 0, "yes", "no") -> yes
A33: A18519207 | B33: {=index(PIDtoTSN!E:E, match(A33, PIDtoTSN!A:A, 0))} -> 200047647 | C33: Jacob Kavanal | D33: jkavanal@ucsd.edu | E33: D37 | F33: {=index('Mentor Choices'!B:B, match(E33, 'Mentor Choices'!A:A, 0))} -> Renu Raman | G33: =IF(COUNTIF(Sept16!C:C, B33) > 0, "yes", "no") -> yes
A34: A16803192 | B34: {=index(PIDtoTSN!E:E, match(A34, PIDtoTSN!A:A, 0))} -> 200293399 | C34: Michael Petersen | D34: m1petersen@ucsd.edu | E34: D12 | F34: {=index('Mentor Choices'!B:B, match(E34, 'Mentor Choices'!A:A, 0))} -> Kyle Nero | G34: =IF(COUNTIF(Sept16!C:C, B34) > 0, "yes", "no") -> yes
A35: A17407878 | B35: {=index(PIDtoTSN!E:E, match(A35, PIDtoTSN!A:A, 0))} -> 200219387 | C35: Uzair Gheewala | D35: ugheewala@ucsd.edu | E35: D04 | F35: {=index('Mentor Choices'!B:B, match(E35, 'Mentor Choices'!A:A, 0))} -> Biwei Huang | G35: =IF(COUNTIF(Sept16!C:C, B35) > 0, "yes", "no") -> yes
A36: A17432350 | B36: {=index(PIDtoTSN!E:E, match(A36, PIDtoTSN!A:A, 0))} -> 200217277 | C36: Vanshika Somani | D36: vsomani@ucsd.edu | E36: D29 | F36: {=index('Mentor Choices'!B:B, match(E36, 'Mentor Choices'!A:A, 0))} -> Stuart Geiger | G36: =IF(COUNTIF(Sept16!C:C, B36) > 0, "yes", "no") -> yes
A37: A17458837 | B37: {=index(PIDtoTSN!E:E, match(A37, PIDtoTSN!A:A, 0))} -> 200215713 | C37: Faline Le | D37: fnle@ucsd.edu | E37: D42 | F37: {=index('Mentor Choices'!B:B, match(E37, 'Mentor Choices'!A:A, 0))} -> Bijian Arbab | G37: =IF(COUNTIF(Sept16!C:C, B37) > 0, "yes", "no") -> yes
A38: A17500501 | B38: {=index(PIDtoTSN!E:E, match(A38, PIDtoTSN!A:A, 0))} -> 200210305 | C38: Ahmad Ageel | D38: aageel@ucsd.edu | E38: D09 | F38: {=index('Mentor Choices'!B:B, match(E38, 'Mentor Choices'!A:A, 0))} -> Igor Sfiligoi | G38: =IF(COUNTIF(Sept16!C:C, B38) > 0, "yes", "no") -> yes
A39: A17531851 | B39: {=index(PIDtoTSN!E:E, match(A39, PIDtoTSN!A:A, 0))} -> 200208439 | C39: Abdulrahim Ham | D39: amham@ucsd.edu | E39: D18 | F39: {=index('Mentor Choices'!B:B, match(E39, 'Mentor Choices'!A:A, 0))} -> Tiffany Amariuta | G39: =IF(COUNTIF(Sept16!C:C, B39) > 0, "yes", "no") -> yes
A40: A17704905 | B40: {=index(PIDtoTSN!E:E, match(A40, PIDtoTSN!A:A, 0))} -> 200183188 | C40: Viki Shi | D40: vishi@ucsd.edu | E40: D28 | F40: {=index('Mentor Choices'!B:B, match(E40, 'Mentor Choices'!A:A, 0))} -> Ryan Lingo | G40: =IF(COUNTIF(Sept16!C:C, B40) > 0, "yes", "no") -> yes
A41: A17710940 | B41: {=index(PIDtoTSN!E:E, match(A41, PIDtoTSN!A:A, 0))} -> 200184024 | C41: Mohak Prakash | D41: mprakash@ucsd.edu | E41: D27 | F41: {=index('Mentor Choices'!B:B, match(E41, 'Mentor Choices'!A:A, 0))} -> Misha Belkin | G41: =IF(COUNTIF(Sept16!C:C, B41) > 0, "yes", "no") -> yes
...

Sheet AllocStats
A1: Metric | B1: Value | E1: Choice | F1: Students | I1: PID | J1: Name | K1: Email | L1: Domain ID
A2: Students | B2: 310 | E2: 1 | F2: 156 | I2: A17372335 | J2: Amjad Faiz Bin Muhamad Afandy | K2: amuhamadafandy@ucsd.edu | L2: D27
A3: Domains | B3: 44 | E3: 2 | F3: 39 | I3: A17500501 | J3: Ahmad Ageel | K3: aageel@ucsd.edu | L3: D09
A4: Total seats | B4: 317 | E4: 3 | F4: 26 | I4: A17710940 | J4: Mohak Prakash | K4: mprakash@ucsd.edu | L4: D27
A5: Matched | B5: 310 | E5: 4 | F5: 21 | I5: A17752898 | J5: Vedant Vardhaan | K5: vvardhaan@ucsd.edu | L5: D32
A6: Unmatched | B6: 0 | E6: 5 | F6: 9 | I6: A17784858 | J6: Hasaam Butt | K6: hbutt@ucsd.edu | L6: D27
A7: Fallback placements | B7: 20 | E7: 6 | F7: 13 | I7: A17809290 | J7: Shunyi Du | K7: shunyidu@gmail.com | L7: D27
A8: Blocking pairs | B8: 0 | E8: 7 | F8: 6 | I8: A17813042 | J8: Aathi Muthu | K8: amuthu@ucsd.edu | L8: D32
A9: Capacity violations | B9: 0 | E9: 8 | F9: 9 | I9: A17897553 | J9: Jaden Vo | K9: j9vo@ucsd.edu | L9: D32
A10: Got 1st choice | B10: 156 | E10: 9 | F10: 4 | I10: A17897956 | J10: Dylan Vo | K10: dyvo@ucsd.edu | L10: D09
A11: Got a top-3 choice | B11: 221 | E11: 10 | F11: 7 | I11: A17920037 | J11: Flavia Gabriella Tedjarutjianta | K11: ftedjarutjianta@ucsd.edu | L11: D27
E12: fallback | F12: 20 | I12: A18115979 | J12: Brian Can | K12: brcan@ucsd.edu | L12: D32
I13: A18176347 | J13: Nimisha Mishra | K13: n2mishra@ucsd.edu | L13: D32
I14: A18498019 | J14: Andrew Youn | K14: asyoun@ucsd.edu | L14: D32
I15: A18503664 | J15: Po-Hua Chen | K15: poc008@ucsd.edu | L15: D32
I16: A18506910 | J16: Anand Baidya | K16: abaidya@ucsd.edu | L16: D32
I17: A18507432 | J17: Khaleel Karim | K17: kkarim@ucsd.edu | L17: D09
I18: A18534525 | J18: Junle Li | K18: jul187@ucsd.edu | L18: D09
I19: A18562616 | J19: Janie Chan | K19: jlc006@ucsd.edu | L19: D27
I20: A18579846 | J20: Prabhjas Singh | K20: prs018@ucsd.edu | L20: D27
I21: A18589762 | J21: Sonali Singh | K21: sssingh@ucsd.edu | L21: D27

Sheet mentors
A1: Domain ID | B1: First Name | C1: Last Name | D1: Email | E1: Full Name | F1: Students Allocated
A2: D01 | B2: Ali | C2: Arsanjani | D2: arsanjani@google.com | E2: =CONCATENATE(B2, " ", C2) -> Ali Arsanjani | F2: {=index(bydomain!F:F, match(A2, bydomain!A:A, 0))} -> Akshitaa Balasai, April Huang, Bobby Zhou, Derek Kuang, Ethan Lam, Grace Trainor, Hannah Gonzalez, Janice Rincon, Jordi Pham, Kyle Flores, Rezon Gautama, Saanvi Ranadive, Susana Haing, Vanessa Lau, Zachary Loo, Sonali Singh
A3: D02 | B3: Aobo | C3: Li | D3: aol002@ucsd.edu | E3: =CONCATENATE(B3, " ", C3) -> Aobo Li | F3: {=index(bydomain!F:F, match(A3, bydomain!A:A, 0))} -> Bryan Cruz, Hieu Nguyen, Madhav Pudukottai Krishnaraj, Ryan Conrad Atienza, Timothy Harmon
A4: D03 | B4: Ben | C4: Smarr | D4: bsmarr@ucsd.edu | E4: =CONCATENATE(B4, " ", C4) -> Ben Smarr | F4: {=index(bydomain!F:F, match(A4, bydomain!A:A, 0))} -> Alisha Wang, Brandon Van Horn, Matthew Vaught, Vivian Lin
A5: D03 | B5: Manny | C5: Ruidiaz | D5: manny.ruidiaz@murine.org | E5: =CONCATENATE(B5, " ", C5) -> Manny Ruidiaz | F5: {=index(bydomain!F:F, match(A5, bydomain!A:A, 0))} -> Alisha Wang, Brandon Van Horn, Matthew Vaught, Vivian Lin
A6: D04 | B6: Biwei | C6: Huang | D6: bih007@ucsd.edu | E6: =CONCATENATE(B6, " ", C6) -> Biwei Huang | F6: {=index(bydomain!F:F, match(A6, bydomain!A:A, 0))} -> Bryan Nguyen, Joey Sandoval, Juee Deshmukh, Kyle Zhao, Palina Volskaya, Scarlett Scott, Uzair Gheewala, Vani Sahjwani
A7: D05 | B7: Haojian | C7: Jin | D7: haojian@ucsd.edu | E7: =CONCATENATE(B7, " ", C7) -> Haojian Jin | F7: {=index(bydomain!F:F, match(A7, bydomain!A:A, 0))} -> Ali Ahmed, Claire Lee, Daniel Huang, David Chew, Jared Parra, Justin Lee, Keanu Ventura, Lillian Tran, Marvell Suhali, Matthew Justine Viray, Ryan Lee, Sharon Tey
A8: D05 | B8: Michael | C8: Deisher | D8: michael.deisher@azimuth-ai.com | E8: =CONCATENATE(B8, " ", C8) -> Michael Deisher | F8: {=index(bydomain!F:F, match(A8, bydomain!A:A, 0))} -> Ali Ahmed, Claire Lee, Daniel Huang, David Chew, Jared Parra, Justin Lee, Keanu Ventura, Lillian Tran, Marvell Suhali, Matthew Justine Viray, Ryan Lee, Sharon Tey
A9: D05 | B9: Sylvia | C9: Downing | D9: sylvia.j.downing@azimuth-ai.com | E9: =CONCATENATE(B9, " ", C9) -> Sylvia Downing | F9: {=index(bydomain!F:F, match(A9, bydomain!A:A, 0))} -> Ali Ahmed, Claire Lee, Daniel Huang, David Chew, Jared Parra, Justin Lee, Keanu Ventura, Lillian Tran, Marvell Suhali, Matthew Justine Viray, Ryan Lee, Sharon Tey
A10: D06 | B10: Duncan | C10: Watson-Parris | D10: dwatsonparris@ucsd.edu | E10: =CONCATENATE(B10, " ", C10) -> Duncan Watson-Parris | F10: {=index(bydomain!F:F, match(A10, bydomain!A:A, 0))} -> Annaly Ellis, Cheryl Xiang, Coleman Clougherty, Coltrane Gowan, Jennifer Chang, Linus Lee, Roman Respicio, Vishal Rana Paidi
A11: D07 | B11: Emily | C11: Aiken | D11: eaiken@ucsd.edu | E11: =CONCATENATE(B11, " ", C11) -> Emily Aiken | F11: {=index(bydomain!F:F, match(A11, bydomain!A:A, 0))} -> Margot Nissen, Maya Sissel, Mieko Chun, Prisha Maiti, Simone Rao, Su Love Wai
A12: D08 | B12: Gabriel | C12: Andres Garzo | D12: gabrielandres.garzo@rpsandiego.com | E12: =CONCATENATE(B12, " ", C12) -> Gabriel Andres Garzo | F12: {=index(bydomain!F:F, match(A12, bydomain!A:A, 0))} -> Audrey Chung, Gabriel Maayah, Kang Lee, Kate Feng, Keilani Li, Siya Sathaye, Tiantian Zheng, Tristan Leo
A13: D08 | B13: Madison | C13: Hughes | D13: madison.hughes@rpsandiego.com | E13: =CONCATENATE(B13, " ", C13) -> Madison Hughes | F13: {=index(bydomain!F:F, match(A13, bydomain!A:A, 0))} -> Audrey Chung, Gabriel Maayah, Kang Lee, Kate Feng, Keilani Li, Siya Sathaye, Tiantian Zheng, Tristan Leo
... A67: D44 | B67: Robert | C67: Wilderman | D67: robert.wildeman@us.bosch.com | E67: =CONCATENATE(B67, " ", C67) -> Robert Wilderman | F67: {=index(bydomain!F:F, match(A67, bydomain!A:A, 0))} -> Ansh Bhatnagar, Chang-Yu Lee, Jayden Huang, Jeronimo Adames-Baena, Mihir Vad, Shujia Chen, Sunny Sun, Varick Hasim
A68: D45 | B68: Soohyun | C68: Liao | D68: snam@ucsd.edu | E68: Soohyun Liao

Sheet enrollment
A1: Select Mentor from Dropdown | E1: Select Domain ID from Dropdown
A3: Aobo Li | B3: {=index(mentors!A:A, match(A3, mentors!E:E, 0))} -> D02 | D3: Mentors for domain | E3: D12 | F3: =E3 -> D12 | H3: Mentors for domain
A5: =IFERROR(__xludf.DUMMYFUNCTION("IF(OR(A3="""",A3=""Full Name""), ""Please select a mentor."", FILTER(bystudent!B:D , bystudent!E:E = B3))"),"#REF!") -> #REF! | D5: =IFERROR(__xludf.DUMMYFUNCTION("IF(OR(A3="""",A3=""Domain ID""), ""Please select a Domain."", FILTER(mentors!E:E ,mentors!A:A = B3))"),"Aobo Li") -> Aobo Li | E5: =IFERROR(__xludf.DUMMYFUNCTION("IF(OR(E3="""",E3=""Domain ID""), ""Please select a Domain."", FILTER(bystudent!B:D ,bystudent!E:E = F3))"),2.00173831E8) -> 200173831 | F5: =IFERROR(__xludf.DUMMYFUNCTION("""COMPUTED_VALUE"""),"Song Su") -> Song Su | G5: =IFERROR(__xludf.DUMMYFUNCTION("""COMPUTED_VALUE"""),"sosu@ucsd.edu") -> sosu@ucsd.edu | H5: =IFERROR(__xludf.DUMMYFUNCTION("IF(OR(E3="""",E3=""Domain ID""), ""Please select a Domain."", FILTER(mentors!E:E ,mentors!A:A = F3))"),"Kyle Nero") -> Kyle Nero
E6: =IFERROR(__xludf.DUMMYFUNCTION("""COMPUTED_VALUE"""),2.00144405E8) -> 200144405 | F6: =IFERROR(__xludf.DUMMYFUNCTION("""COMPUTED_VALUE"""),"Steven Ouyang") -> Steven Ouyang | G6: =IFERROR(__xludf.DUMMYFUNCTION("""COMPUTED_VALUE"""),"houyang@ucsd.edu") -> houyang@ucsd.edu | H6: =IFERROR(__xludf.DUMMYFUNCTION("""COMPUTED_VALUE"""),"Daniel Mathew") -> Daniel Mathew
E7: =IFERROR(__xludf.DUMMYFUNCTION("""COMPUTED_VALUE"""),2.00114926E8) -> 200114926 | F7: =IFERROR(__xludf.DUMMYFUNCTION("""COMPUTED_VALUE"""),"Vanessa Feng") -> Vanessa Feng | G7: =IFERROR(__xludf.DUMMYFUNCTION("""COMPUTED_VALUE"""),"l6feng@ucsd.edu") -> l6feng@ucsd.edu | H7: =IFERROR(__xludf.DUMMYFUNCTION("""COMPUTED_VALUE"""),"Berk Ustun") -> Berk Ustun
E8: =IFERROR(__xludf.DUMMYFUNCTION("""COMPUTED_VALUE"""),2.00293399E8) -> 200293399 | F8: =IFERROR(__xludf.DUMMYFUNCTION("""COMPUTED_VALUE"""),"Michael Petersen") -> Michael Petersen | G8: =IFERROR(__xludf.DUMMYFUNCTION("""COMPUTED_VALUE"""),"m1petersen@ucsd.edu") -> m1petersen@ucsd.edu
C9: I | E9: =IFERROR(__xludf.DUMMYFUNCTION("""COMPUTED_VALUE"""),2.00175198E8) -> 200175198 | F9: =IFERROR(__xludf.DUMMYFUNCTION("""COMPUTED_VALUE"""),"Ishaan Tibdewal") -> Ishaan Tibdewal | G9: =IFERROR(__xludf.DUMMYFUNCTION("""COMPUTED_VALUE"""),"itibdewal@ucsd.edu") -> itibdewal@ucsd.edu
E10: =IFERROR(__xludf.DUMMYFUNCTION("""COMPUTED_VALUE"""),2.00166599E8) -> 200166599 | F10: =IFERROR(__xludf.DUMMYFUNCTION("""COMPUTED_VALUE"""),"Katie Hannigan") -> Katie Hannigan | G10: =IFERROR(__xludf.DUMMYFUNCTION("""COMPUTED_VALUE"""),"khannigan@ucsd.edu") -> khannigan@ucsd.edu
E11: =IFERROR(__xludf.DUMMYFUNCTION("""COMPUTED_VALUE"""),2.00167956E8) -> 200167956 | F11: =IFERROR(__xludf.DUMMYFUNCTION("""COMPUTED_VALUE"""),"Aiden Lai") -> Aiden Lai | G11: =IFERROR(__xludf.DUMMYFUNCTION("""COMPUTED_VALUE"""),"ailai@ucsd.edu") -> ailai@ucsd.edu
E12: =IFERROR(__xludf.DUMMYFUNCTION("""COMPUTED_VALUE"""),2.00145085E8) -> 200145085 | F12: =IFERROR(__xludf.DUMMYFUNCTION("""COMPUTED_VALUE"""),"Sam Ouyang") -> Sam Ouyang | G12: =IFERROR(__xludf.DUMMYFUNCTION("""COMPUTED_VALUE"""),"saouyang@ucsd.edu") -> saouyang@ucsd.edu
E13: =IFERROR(__xludf.DUMMYFUNCTION("""COMPUTED_VALUE"""),2.00134986E8) -> 200134986 | F13: =IFERROR(__xludf.DUMMYFUNCTION("""COMPUTED_VALUE"""),"Huiyu Yie") -> Huiyu Yie | G13: =IFERROR(__xludf.DUMMYFUNCTION("""COMPUTED_VALUE"""),"huyie@ucsd.edu") -> huyie@ucsd.edu
E14: =IFERROR(__xludf.DUMMYFUNCTION("""COMPUTED_VALUE"""),2.00116919E8) -> 200116919 | F14: =IFERROR(__xludf.DUMMYFUNCTION("""COMPUTED_VALUE"""),"Zilig Xu") -> Zilig Xu | G14: =IFERROR(__xludf.DUMMYFUNCTION("""COMPUTED_VALUE"""),"zix021@ucsd.edu") -> zix021@ucsd.edu
E15: =IFERROR(__xludf.DUMMYFUNCTION("""COMPUTED_VALUE"""),2.00071579E8) -> 200071579 | F15: =IFERROR(__xludf.DUMMYFUNCTION("""COMPUTED_VALUE"""),"Jack Ding") -> Jack Ding | G15: =IFERROR(__xludf.DUMMYFUNCTION("""COMPUTED_VALUE"""),"jading@ucsd.edu") -> jading@ucsd.edu
E16: =IFERROR(__xludf.DUMMYFUNCTION("""COMPUTED_VALUE"""),2.00049942E8) -> 200049942 | F16: =IFERROR(__xludf.DUMMYFUNCTION("""COMPUTED_VALUE"""),"Liuxuhong Zhao") -> Liuxuhong Zhao | G16: =IFERROR(__xludf.DUMMYFUNCTION("""COMPUTED_VALUE"""),"liz066@ucsd.edu") -> liz066@ucsd.edu

Sheet PIDtoTSN
A1: PID | B1: Name | C1: Email | D1: TSN | E1: FLAT
A2: A18654426 | B2: Julia Dial | C2: jrdial@ucsd.edu | D2: =IFERROR(VLOOKUP(C2,TSN,2,FALSE),"None") -> None | E2: 200016088
A3: A18633328 | B3: Juee Deshmukh | C3: jdeshmukh@ucsd.edu | D3: =IFERROR(VLOOKUP(C3,TSN,2,FALSE),"None") -> None | E3: 200020274
A4: A18633375 | B4: Jayden Li | C4: jbl011@ucsd.edu | D4: =IFERROR(VLOOKUP(C4,TSN,2,FALSE),"None") -> None | E4: 200020279
A5: A18639524 | B5: Rishvik Ravi | C5: r4ravi@ucsd.edu | D5: =IFERROR(VLOOKUP(C5,TSN,2,FALSE),"None") -> None | E5: 200021549
A6: A18647188 | B6: Arushi Patra | C6: apatra@ucsd.edu | D6: =IFERROR(VLOOKUP(C6,TSN,2,FALSE),"None") -> None | E6: 200022960
A7: A18615626 | B7: Dylan Louie | C7: dylouie@ucsd.edu | D7: =IFERROR(VLOOKUP(C7,TSN,2,FALSE),"None") -> None | E7: 200024521
A8: A18616536 | B8: Zonglin Zhang | C8: zoz002@ucsd.edu | D8: =IFERROR(VLOOKUP(C8,TSN,2,FALSE),"None") -> None | E8: 200024714
A9: A18598144 | B9: Kavyan Patel | C9: kpp007@ucsd.edu | D9: =IFERROR(VLOOKUP(C9,TSN,2,FALSE),"None") -> None | E9: 200028239
A10: A18603940 | B10: Sweekrit Bhatnagar | C10: sbhatnagar@ucsd.edu | D10: =IFERROR(VLOOKUP(C10,TSN,2,FALSE),"None") -> None | E10: 200030009
A11: A18605782 | B11: Sumedha Rai | C11: surai@ucsd.edu | D11: =IFERROR(VLOOKUP(C11,TSN,2,FALSE),"None") -> None | E11: 200030407
A12: A18606977 | B12: Brian Jing | C12: bjing@ucsd.edu | D12: =IFERROR(VLOOKUP(C12,TSN,2,FALSE),"None") -> None | E12: 200030722
A13: A18609679 | B13: Siya Sathaye | C13: ssathaye@ucsd.edu | D13: =IFERROR(VLOOKUP(C13,TSN,2,FALSE),"None") -> None | E13: 200031205
... A203: A17843999 | B203: Mehul Verma | C203: meverma@ucsd.edu | D203: =IFERROR(VLOOKUP(C203,TSN,2,FALSE),"None") -> None | E203: 200160647
A204: 200160710 | B204: Jenny Xu | C204: jex004@ucsd.edu | D204: =IFERROR(VLOOKUP(C204,TSN,2,FALSE),"None") -> None | E204: 200160710
A205: A17844626 | B205: Neil Dewan | C205: ndewan@ucsd.edu | D205: =IFERROR(VLOOKUP(C205,TSN,2,FALSE),"None") -> None | E205: 200160765
A206: A17846462 | B206: Edison Ayran | C206: edayran@ucsd.edu | D206: =IFERROR(VLOOKUP(C206,TSN,2,FALSE),"None") -> None | E206: 200161135
A207: A17847114 | B207: Chidiebere Agunanne | C207: cagunanne@ucsd.edu | D207: =IFERROR(VLOOKUP(C207,TSN,2,FALSE),"None") -> None | E207: 200161275
A208: A17847578 | B208: Jason Liu | C208: jal134@ucsd.edu | D208: =IFERROR(VLOOKUP(C208,TSN,2,FALSE),"None") -> None | E208: 200161391
A209: A17848067 | B209: Atherv Vidhate | C209: avidhate@ucsd.edu | D209: =IFERROR(VLOOKUP(C209,TSN,2,FALSE),"None") -> None | E209: 200161521
A210: A17848688 | B210: Deepal Deleena | C210: ddeleena@ucsd.edu | D210: =IFERROR(VLOOKUP(C210,TSN,2,FALSE),"None") -> None | E210: 200161621
A211: A17849396 | B211: Kyle Flores | C211: kyflores@ucsd.edu | D211: =IFERROR(VLOOKUP(C211,TSN,2,FALSE),"None") -> None | E211: 200161763
A212: A17852643 | B212: Munachimso Ndubisi | C212: mndubisi@ucsd.edu | D212: =IFERROR(VLOOKUP(C212,TSN,2,FALSE),"None") -> None | E212: 200162254
A213: A17853057 | B213: Hieu Nguyen | C213: vin028@ucsd.edu | D213: =IFERROR(VLOOKUP(C213,TSN,2,FALSE),"None") -> None | E213: 200162298
A214: A17853531 | B214: Yi-Hsuan Kuo | C214: y3kuo@ucsd.edu | D214: =IFERROR(VLOOKUP(C214,TSN,2,FALSE),"None") -> None | E214: 200162375
A215: A17853863 | B215: Varick Hasim | C215: vhasim@ucsd.edu | D215: =IFERROR(VLOOKUP(C215,TSN,2,FALSE),"None") -> None | E215: 200162425
A216: A17853941 | B216: Dhruv Sehgal | C216: dsehgal@ucsd.edu | D216: =IFERROR(VLOOKUP(C216,TSN,2,FALSE),"None") -> None | E216: 200162446
... A227: A17830823 | B227: William Chou | C227: w4chou@ucsd.edu | D227: =IFERROR(VLOOKUP(C227,TSN,2,FALSE),"None") -> None | E227: 200164928
A228: 200164955 | B228: Willem De Haan | C228: wdehaan@ucsd.edu | D228: =IFERROR(VLOOKUP(C228,TSN,2,FALSE),"None") -> None | E228: 200164955
A229: A17832678 | B229: Eric Gan | C229: ergan@ucsd.edu | D229: =IFERROR(VLOOKUP(C229,TSN,2,FALSE),"None") -> None | E229: 200165233
